Workbook

Sheet CMFA-CSCDA Grants
A1: Project ID | B1: Property Name | C1: Applicant / Entity | D1: City | E1: County | F1: Agency | G1: Grant Description | H1: Resolution | I1: Date | J1: DEAD? | K1: Investor 1 | L1: Investor 2 | M1: Nonprofit Partner | N1: Stale | O1: Total Unit Count | P1: Restricted Unit Count | Q1: Restricted Ratio | R1: Address | S1: City's Cut | T1: Parcel Identified | U1: Welfare Exemption On 2025 Roll | V1: Total Roll Value | W1: Confirmed Exemption | X1: Best Estimate Exemption | Y1: Confirmed or Best Estimate Exemption | Z1: Tax Rate | AA1: Confirmed Annual Revenue Loss | AB1: Best Estimate Annual Revenue Loss | AC1: Link | AD1: Leasing Link | AE1: New build? | AF1: Built | AG1: Acquisition Price (M) | AH1: Acquisition Date | AI1: Regulatory Term | AJ1: Closing Fee | AK1: CMFA Annual Fee | AL1: YEARS IN SERVICE | AM1: ANNUAL FEES PAID | AN1: SCC FILED?
A2: 238 | B2: Heritage Park Apartments Livermore | C2: Standard Heritage Livermore Owner LP | D2: Livermore | E2: Alameda | F2: CMFA | G2: Loan / $100,000 | I2: 44659 | K2: Standard Property Company | M2: Housing on Merit | N2: FALSE | O2: 167 | P2: 125 | R2: 900 E Stanley Blvd, Livermore, CA 94550 | AE2: NO | AF2: 1988 | AJ2: =if(F2="CMFA", if(O2<16,10000,O2*600),if(F2="CSCDA",if(33<O2<300, O2*600,if(O2>300,(180000+(O2-300)*300),20000)))) -> 100200 | AK2: =if(F2="CMFA", if(O2<26,4000,O2*150),if(F2="CSCDA",if(33<O2<300, O2*150,if(O2>300,(45000+(O2-300)*75),5000)))) -> 25050 | AL2: =if(AE2="YES",0,IF(AND(I2>=DATE(2022,7,1),I2<=DATE(2023,6,30)),3,IF(AND(I2>=DATE(2023,7,1),I2<=DATE(2024,6,30)),2,IF(AND(I2>=DATE(2024,7,1),I2<=DATE(2025,6,30)),1,IF(AND(I2>=DATE(2025,7,1),I2<=DATE(2026,6,30)),0,"-"))))) -> - | AM2: =AK2*AL2 -> #VALUE! | AN2: TRUE
A3: 192 | B3: Heritage Village Anaheim Apartments | C3: Standard Heritage Anaheim Owner LP | D3: Anaheim | E3: Orange | F3: CMFA | G3: Loan / $100,000 | I3: 44666 | K3: Standard Property Company | M3: Housing on Merit | N3: FALSE | O3: 196 | P3: 157 | Q3: =P3/O3 -> 0.80102041 | R3: 707 W Santa Ana Street, Anaheim CA 92805 | S3: 16850 | T3: =COUNTIF(Parcels!A:A, A3) > 0 -> TRUE | U3: =MAXIFS(Parcels!AC:AC, Parcels!A:A, A3) > 0 -> TRUE | V3: =SUMIF(Parcels!A:A, A3, Parcels!Z:Z) -> 67860998 | W3: =SUMIF(Parcels!$A:$A, $A3, Parcels!AC:AC) -> 67860998 | X3: =V3*P3/O3*0.9 -> 48922240 | Y3: =IF(W3=0, X3, W3) -> 67860998 | Z3: {=_xlfn.XLOOKUP( A3, Parcels!A:A, Parcels!AL:AL)} | AA3: =W3*Z3 -> 0 | AB3: =Y3*Z3 -> 0 | AJ3: =if(F3="CMFA", if(O3<16,10000,O3*600),if(F3="CSCDA",if(33<O3<300, O3*600,if(O3>300,(180000+(O3-300)*300),20000)))) -> 117600 | AK3: =if(F3="CMFA", if(O3<26,4000,O3*150),if(F3="CSCDA",if(33<O3<300, O3*150,if(O3>300,(45000+(O3-300)*75),5000)))) -> 29400 | AL3: =if(AE3="YES",0,IF(AND(I3>=DATE(2022,7,1),I3<=DATE(2023,6,30)),3,IF(AND(I3>=DATE(2023,7,1),I3<=DATE(2024,6,30)),2,IF(AND(I3>=DATE(2024,7,1),I3<=DATE(2025,6,30)),1,IF(AND(I3>=DATE(2025,7,1),I3<=DATE(2026,6,30)),0,"-"))))) -> - | AM3: =AK3*AL3 -> #VALUE! | AN3: TRUE
A4: 193 | B4: Heritage Park Escondido Apartments | C4: STANDARD HERITAGE ESCONDIDO OWNER LP | D4: Escondido | E4: San Diego | F4: CMFA | G4: Loan / $100,000 | I4: 44666 | K4: Standard Property Company | M4: Housing on Merit | N4: FALSE | O4: 196 | P4: 157 | Q4: =P4/O4 -> 0.80102041 | R4: 2549 E. Valley Parkway, Escondido, CA 92027 | S4: 15766 | T4: =COUNTIF(Parcels!A:A, A4) > 0 -> TRUE | U4: =MAXIFS(Parcels!AC:AC, Parcels!A:A, A4) > 0 -> TRUE | V4: =SUMIF(Parcels!A:A, A4, Parcels!Z:Z) -> 49668778 | W4: =SUMIF(Parcels!$A:$A, $A4, Parcels!AC:AC) -> 49157189 | X4: =V4*P4/O4*0.9 -> 35807134 | Y4: =IF(W4=0, X4, W4) -> 49157189 | Z4: {=_xlfn.XLOOKUP( A4, Parcels!A:A, Parcels!AL:AL)} | AA4: =W4*Z4 -> 0 | AJ4: =if(F4="CMFA", if(O4<16,10000,O4*600),if(F4="CSCDA",if(33<O4<300, O4*600,if(O4>300,(180000+(O4-300)*300),20000)))) -> 117600 | AK4: =if(F4="CMFA", if(O4<26,4000,O4*150),if(F4="CSCDA",if(33<O4<300, O4*150,if(O4>300,(45000+(O4-300)*75),5000)))) -> 29400 | AL4: =if(AE4="YES",0,IF(AND(I4>=DATE(2022,7,1),I4<=DATE(2023,6,30)),3,IF(AND(I4>=DATE(2023,7,1),I4<=DATE(2024,6,30)),2,IF(AND(I4>=DATE(2024,7,1),I4<=DATE(2025,6,30)),1,IF(AND(I4>=DATE(2025,7,1),I4<=DATE(2026,6,30)),0,"-"))))) -> - | AM4: =AK4*AL4 -> #VALUE! | AN4: {=_xlfn.xlookup(C4,'SCC Certificate Review'!C:C,'SCC Certificate Review'!F:F)} -> #N/A
A5: 1 | B5: Alvarado Streets Apartments | C5: Alvarado Affordable Associates, LP | D5: Los Angeles | E5: Los Angeles | F5: CMFA | G5: Grant up to $10,000 | H5: 23-204 | I5: 45121 | K5: Taylor Equities | M5: Kingdom Development, Inc. | N5: FALSE | O5: 24 | P5: 24 | Q5: =P5/O5 -> 1 | R5: 1136 S. Alvarado Street, Los Angeles, CA | S5: 3600 | T5: =COUNTIF(Parcels!A:A, A5) > 0 -> TRUE | U5: =MAXIFS(Parcels!AC:AC, Parcels!A:A, A5) > 0 -> TRUE | V5: =SUMIF(Parcels!A:A, A5, Parcels!Z:Z) -> 4447710 | W5: =SUMIF(Parcels!$A:$A, $A5, Parcels!AC:AC) -> 4262686 | X5: =V5*P5/O5*0.9 -> 4002939 | Y5: =IF(W5=0, X5, W5) -> 4262686 | Z5: {=_xlfn.XLOOKUP( A5, Parcels!A:A, Parcels!AL:AL)} -> 0.0118738 | AA5: =W5*Z5 -> 50614.281 | AB5: =Y5*Z5 -> 50614.281 | AJ5: =if(F5="CMFA", if(O5<16,10000,O5*600),if(F5="CSCDA",if(33<O5<300, O5*600,if(O5>300,(180000+(O5-300)*300),20000)))) -> 14400 | AK5: =if(F5="CMFA", if(O5<26,4000,O5*150),if(F5="CSCDA",if(33<O5<300, O5*150,if(O5>300,(45000+(O5-300)*75),5000)))) -> 4000 | AL5: =if(AE5="YES",0,IF(AND(I5>=DATE(2022,7,1),I5<=DATE(2023,6,30)),3,IF(AND(I5>=DATE(2023,7,1),I5<=DATE(2024,6,30)),2,IF(AND(I5>=DATE(2024,7,1),I5<=DATE(2025,6,30)),1,IF(AND(I5>=DATE(2025,7,1),I5<=DATE(2026,6,30)),0,"-"))))) -> 2 | AM5: =AK5*AL5 -> 8000 | AN5: {=_xlfn.xlookup(C5,'SCC Certificate Review'!C:C,'SCC Certificate Review'!F:F)} -> TRUE
A6: 4 | B6: Bernardine Apartments | C6: Castle Rock Bernardine Apartments, LP | D6: San Bernardino | E6: San Bernardino | F6: CMFA | G6: Grant up to $10,000 | H6: 23-222 | I6: 45142 | K6: Quest Capital Partners | M6: Affordable Rent Project | N6: FALSE | O6: 71 | P6: 70 | R6: 363 E. Gilbert St., San Bernardino, CA | S6: 10650 | T6: =COUNTIF(Parcels!A:A, A6) > 0 -> TRUE | U6: =MAXIFS(Parcels!AC:AC, Parcels!A:A, A6) > 0 -> TRUE | V6: =SUMIF(Parcels!A:A, A6, Parcels!Z:Z) -> 4156500 | W6: =SUMIF(Parcels!$A:$A, $A6, Parcels!AC:AC) -> 4156500 | X6: =V6*P6/O6*0.9 -> 3688162 | Y6: =IF(W6=0, X6, W6) -> 4156500 | Z6: {=_xlfn.XLOOKUP( A6, Parcels!A:A, Parcels!AL:AL)} -> 0.0113 | AA6: =W6*Z6 -> 46968.45 | AB6: =Y6*Z6 -> 46968.45 | AJ6: =if(F6="CMFA", if(O6<16,10000,O6*600),if(F6="CSCDA",if(33<O6<300, O6*600,if(O6>300,(180000+(O6-300)*300),20000)))) -> 42600 | AK6: =if(F6="CMFA", if(O6<26,4000,O6*150),if(F6="CSCDA",if(33<O6<300, O6*150,if(O6>300,(45000+(O6-300)*75),5000)))) -> 10650 | AL6: =if(AE6="YES",0,IF(AND(I6>=DATE(2022,7,1),I6<=DATE(2023,6,30)),3,IF(AND(I6>=DATE(2023,7,1),I6<=DATE(2024,6,30)),2,IF(AND(I6>=DATE(2024,7,1),I6<=DATE(2025,6,30)),1,IF(AND(I6>=DATE(2025,7,1),I6<=DATE(2026,6,30)),0,"-"))))) -> 2 | AM6: =AK6*AL6 -> 21300 | AN6: {=_xlfn.xlookup(C6,'SCC Certificate Review'!C:C,'SCC Certificate Review'!F:F)} -> TRUE
A7: 2 | B7: 2025 New Jersey Apartments | C7: 2025 NJ, LP | D7: Los Angeles | E7: Los Angeles | F7: CMFA | G7: Grant up to $10,000 | H7: 23-223 | I7: 45142 | K7: Eleos Ventures, LLC | M7: Step Forward Communities | N7: FALSE | O7: 15 | P7: 14 | Q7: =P7/O7 -> 0.93333333 | R7: 2025 New Jersey St, Los Angeles, CA | S7: 2250 | T7: =COUNTIF(Parcels!A:A, A7) > 0 -> TRUE | U7: =MAXIFS(Parcels!AC:AC, Parcels!A:A, A7) > 0 -> TRUE | V7: =SUMIF(Parcels!A:A, A7, Parcels!Z:Z) -> 527950 | W7: =SUMIF(Parcels!$A:$A, $A7, Parcels!AC:AC) -> 527950 | X7: =V7*P7/O7*0.9 -> 443478 | Y7: =IF(W7=0, X7, W7) -> 527950 | Z7: {=_xlfn.XLOOKUP( A7, Parcels!A:A, Parcels!AL:AL)} -> 0.0118738 | AA7: =W7*Z7 -> 6268.7727 | AB7: =Y7*Z7 -> 6268.7727 | AF7: 2023 | AJ7: =if(F7="CMFA", if(O7<16,10000,O7*600),if(F7="CSCDA",if(33<O7<300, O7*600,if(O7>300,(180000+(O7-300)*300),20000)))) -> 10000 | AK7: =if(F7="CMFA", if(O7<26,4000,O7*150),if(F7="CSCDA",if(33<O7<300, O7*150,if(O7>300,(45000+(O7-300)*75),5000)))) -> 4000 | AL7: =if(AE7="YES",0,IF(AND(I7>=DATE(2022,7,1),I7<=DATE(2023,6,30)),3,IF(AND(I7>=DATE(2023,7,1),I7<=DATE(2024,6,30)),2,IF(AND(I7>=DATE(2024,7,1),I7<=DATE(2025,6,30)),1,IF(AND(I7>=DATE(2025,7,1),I7<=DATE(2026,6,30)),0,"-"))))) -> 2 | AM7: =AK7*AL7 -> 8000 | AN7: {=_xlfn.xlookup(C7,'SCC Certificate Review'!C:C,'SCC Certificate Review'!F:F)} -> TRUE
A8: 3 | B8: Mariposa Club Apartments | C8: Mariposa Club Apartments I, LP | D8: Mountain View | E8: Santa Clara | F8: CMFA | G8: Grant up to $10,000 | H8: 23-224 | I8: 45142 | K8: Prometheus Real Estate Group | M8: Hearthstone Housing Foundation | N8: FALSE | O8: 48 | P8: 48 | R8: 660 Mariposa Ave., Mountain View, CA | S8: 7500 | T8: =COUNTIF(Parcels!A:A, A8) > 0 -> TRUE | U8: =MAXIFS(Parcels!AC:AC, Parcels!A:A, A8) > 0 -> TRUE | V8: =SUMIF(Parcels!A:A, A8, Parcels!Z:Z) -> 17059601 | W8: =SUMIF(Parcels!$A:$A, $A8, Parcels!AC:AC) -> 16718409 | X8: =V8*P8/O8*0.9 -> 15353641 | Y8: =IF(W8=0, X8, W8) -> 16718409 | Z8: {=_xlfn.XLOOKUP( A8, Parcels!A:A, Parcels!AL:AL)} -> 0.011211 | AA8: =W8*Z8 -> 187430.08 | AB8: =Y8*Z8 -> 187430.08 | AJ8: =if(F8="CMFA", if(O8<16,10000,O8*600),if(F8="CSCDA",if(33<O8<300, O8*600,if(O8>300,(180000+(O8-300)*300),20000)))) -> 28800 | AK8: =if(F8="CMFA", if(O8<26,4000,O8*150),if(F8="CSCDA",if(33<O8<300, O8*150,if(O8>300,(45000+(O8-300)*75),5000)))) -> 7200 | AL8: =if(AE8="YES",0,IF(AND(I8>=DATE(2022,7,1),I8<=DATE(2023,6,30)),3,IF(AND(I8>=DATE(2023,7,1),I8<=DATE(2024,6,30)),2,IF(AND(I8>=DATE(2024,7,1),I8<=DATE(2025,6,30)),1,IF(AND(I8>=DATE(2025,7,1),I8<=DATE(2026,6,30)),0,"-"))))) -> 2 | AM8: =AK8*AL8 -> 14400 | AN8: {=_xlfn.xlookup(C8,'SCC Certificate Review'!C:C,'SCC Certificate Review'!F:F)} -> TRUE
A9: 5 | B9: City View aka Outlook at Mission Valley Apartments | C9: Mission Valley Preservation LP | D9: San Diego | E9: San Diego | F9: CMFA | G9: Grant up to $10,000 | H9: 23-275 | I9: 45163 | K9: Securities Properties | M9: Las Palmas Housing & Development | N9: FALSE | O9: 56 | P9: 23 | R9: 840 17th St, San Diego, CA 92101 | S9: 8400 | T9: =COUNTIF(Parcels!A:A, A9) > 0 -> TRUE | U9: =MAXIFS(Parcels!AC:AC, Parcels!A:A, A9) > 0 -> FALSE | V9: =SUMIF(Parcels!A:A, A9, Parcels!Z:Z) -> 9316117 | W9: =SUMIF(Parcels!$A:$A, $A9, Parcels!AC:AC) -> 0 | X9: =V9*P9/O9*0.9 -> 3443636.1 | Y9: =IF(W9=0, X9, W9) -> 3443636.1 | Z9: {=_xlfn.XLOOKUP( A9, Parcels!A:A, Parcels!AL:AL)} -> 0.0125114 | AA9: =W9*Z9 -> 0 | AB9: =Y9*Z9 -> 43084.709 | AJ9: =if(F9="CMFA", if(O9<16,10000,O9*600),if(F9="CSCDA",if(33<O9<300, O9*600,if(O9>300,(180000+(O9-300)*300),20000)))) -> 33600 | AK9: =if(F9="CMFA", if(O9<26,4000,O9*150),if(F9="CSCDA",if(33<O9<300, O9*150,if(O9>300,(45000+(O9-300)*75),5000)))) -> 8400 | AL9: =if(AE9="YES",0,IF(AND(I9>=DATE(2022,7,1),I9<=DATE(2023,6,30)),3,IF(AND(I9>=DATE(2023,7,1),I9<=DATE(2024,6,30)),2,IF(AND(I9>=DATE(2024,7,1),I9<=DATE(2025,6,30)),1,IF(AND(I9>=DATE(2025,7,1),I9<=DATE(2026,6,30)),0,"-"))))) -> 2 | AM9: =AK9*AL9 -> 16800 | AN9: {=_xlfn.xlookup(C9,'SCC Certificate Review'!C:C,'SCC Certificate Review'!F:F)} -> TRUE
A10: 6 | B10: 381 Turk Street Apartment | C10: 381 Turk Street Associates | D10: San Francisco | E10: San Francisco | F10: CMFA | G10: Grant up to $10,000 | H10: 23-307 | I10: 45184 | J10: TRUE | K10: Mosser Capital, LLC | M10: Kingdom Development, Inc. | N10: FALSE | O10: 32 | P10: 13 | R10: 381 Turk St., San Francisco, CA | S10: 4800 | T10: =COUNTIF(Parcels!A:A, A10) > 0 -> TRUE | U10: =MAXIFS(Parcels!AC:AC, Parcels!A:A, A10) > 0 -> FALSE | V10: =SUMIF(Parcels!A:A, A10, Parcels!Z:Z) -> 7398189 | W10: =SUMIF(Parcels!$A:$A, $A10, Parcels!AC:AC) -> 0 | X10: =V10*P10/O10*0.9 -> 2704962.9 | Y10: =IF(W10=0, X10, W10) -> 2704962.9 | Z10: {=_xlfn.XLOOKUP( A10, Parcels!A:A, Parcels!AL:AL)} -> 0.012 | AA10: =W10*Z10 -> 0 | AB10: =Y10*Z10 -> 32459.554 | AJ10: =if(F10="CMFA", if(O10<16,10000,O10*600),if(F10="CSCDA",if(33<O10<300, O10*600,if(O10>300,(180000+(O10-300)*300),20000)))) -> 19200 | AK10: =if(F10="CMFA", if(O10<26,4000,O10*150),if(F10="CSCDA",if(33<O10<300, O10*150,if(O10>300,(45000+(O10-300)*75),5000)))) -> 4800 | AL10: =if(AE10="YES",0,IF(AND(I10>=DATE(2022,7,1),I10<=DATE(2023,6,30)),3,IF(AND(I10>=DATE(2023,7,1),I10<=DATE(2024,6,30)),2,IF(AND(I10>=DATE(2024,7,1),I10<=DATE(2025,6,30)),1,IF(AND(I10>=DATE(2025,7,1),I10<=DATE(2026,6,30)),0,"-"))))) -> 2 | AM10: =AK10*AL10 -> 9600 | AN10: {=_xlfn.xlookup(C10,'SCC Certificate Review'!C:C,'SCC Certificate Review'!F:F)}
A11: 7 | B11: Townhomes at Gading Apartments | C11: SFF 2, LLC | D11: Hayward | E11: Alameda | F11: CMFA | G11: Grant up to $10,000 | H11: 23-370 | I11: 45268 | K11: The Sobrato Organization | M11: Sobrato Foundation | N11: FALSE | O11: 61 | P11: 61 | R11: 26409 Gading Rd, Hayward, CA 94544 | S11: 9150 | T11: =COUNTIF(Parcels!A:A, A11) > 0 -> TRUE | U11: =MAXIFS(Parcels!AC:AC, Parcels!A:A, A11) > 0 -> FALSE | V11: =SUMIF(Parcels!A:A, A11, Parcels!Z:Z) -> 17313480 | W11: =SUMIF(Parcels!$A:$A, $A11, Parcels!AC:AC) -> 0 | X11: =V11*P11/O11*0.9 -> 15582132 | Y11: =IF(W11=0, X11, W11) -> 15582132 | Z11: {=_xlfn.XLOOKUP( A11, Parcels!A:A, Parcels!AL:AL)} -> 0.011724 | AA11: =W11*Z11 -> 0 | AB11: =Y11*Z11 -> 182684.92 | AD11: https://www.townhomesongadingapts.com/ | AJ11: =if(F11="CMFA", if(O11<16,10000,O11*600),if(F11="CSCDA",if(33<O11<300, O11*600,if(O11>300,(180000+(O11-300)*300),20000)))) -> 36600 | AK11: =if(F11="CMFA", if(O11<26,4000,O11*150),if(F11="CSCDA",if(33<O11<300, O11*150,if(O11>300,(45000+(O11-300)*75),5000)))) -> 9150 | AL11: =if(AE11="YES",0,IF(AND(I11>=DATE(2022,7,1),I11<=DATE(2023,6,30)),3,IF(AND(I11>=DATE(2023,7,1),I11<=DATE(2024,6,30)),2,IF(AND(I11>=DATE(2024,7,1),I11<=DATE(2025,6,30)),1,IF(AND(I11>=DATE(2025,7,1),I11<=DATE(2026,6,30)),0,"-"))))) -> 2 | AM11: =AK11*AL11 -> 18300 | AN11: {=_xlfn.xlookup(C11,'SCC Certificate Review'!C:C,'SCC Certificate Review'!F:F)}
A12: 8 | B12: 1317 S. Grand Apartments | C12: 1317 SGA QOZB, LP or an affiliate thereof | D12: Los Angeles | E12: Los Angeles | F12: CMFA | H12: 23-371 | I12: 45268 | K12: Housing Diversity Corporation | M12: PEP Housing | N12: FALSE | O12: 147 | P12: 147 | Q12: =P12/O12 -> 1 | R12: 1317 S. Grand St, Los Angeles, CA 90015 | S12: 22050 | T12: =COUNTIF(Parcels!A:A, A12) > 0 -> TRUE | U12: =MAXIFS(Parcels!AC:AC, Parcels!A:A, A12) > 0 -> FALSE | V12: =SUMIF(Parcels!A:A, A12, Parcels!Z:Z) -> 11783947 | W12: =SUMIF(Parcels!$A:$A, $A12, Parcels!AC:AC) -> 0 | X12: =V12*P12/O12*0.9 -> 10605552 | Y12: =IF(W12=0, X12, W12) -> 10605552 | Z12: {=_xlfn.XLOOKUP( A12, Parcels!A:A, Parcels!AL:AL)} -> 0.0118738 | AA12: =W12*Z12 -> 0 | AB12: =Y12*Z12 -> 125928.21 | AJ12: =if(F12="CMFA", if(O12<16,10000,O12*600),if(F12="CSCDA",if(33<O12<300, O12*600,if(O12>300,(180000+(O12-300)*300),20000)))) -> 88200 | AK12: =if(F12="CMFA", if(O12<26,4000,O12*150),if(F12="CSCDA",if(33<O12<300, O12*150,if(O12>300,(45000+(O12-300)*75),5000)))) -> 22050 | AL12: =if(AE12="YES",0,IF(AND(I12>=DATE(2022,7,1),I12<=DATE(2023,6,30)),3,IF(AND(I12>=DATE(2023,7,1),I12<=DATE(2024,6,30)),2,IF(AND(I12>=DATE(2024,7,1),I12<=DATE(2025,6,30)),1,IF(AND(I12>=DATE(2025,7,1),I12<=DATE(2026,6,30)),0,"-"))))) -> 2 | AM12: =AK12*AL12 -> 44100 | AN12: {=_xlfn.xlookup(C12,'SCC Certificate Review'!C:C,'SCC Certificate Review'!F:F)} -> TRUE
A13: 9 | B13: 1411 S. Flower Apartments | C13: Housing Diversity | D13: Los Angeles | E13: Los Angeles | F13: CMFA | H13: 23-372 | I13: 45268 | K13: Housing Diversity Corporation | L13: Arctaris Impact Investors | M13: PEP Housing | N13: FALSE | O13: 227 | P13: 227 | Q13: =P13/O13 -> 1 | R13: 1411 Flower St, Los Angeles, CA 90015 | S13: 34050 | T13: =COUNTIF(Parcels!A:A, A13) > 0 -> TRUE | U13: =MAXIFS(Parcels!AC:AC, Parcels!A:A, A13) > 0 -> FALSE | V13: =SUMIF(Parcels!A:A, A13, Parcels!Z:Z) -> 9142457 | W13: =SUMIF(Parcels!$A:$A, $A13, Parcels!AC:AC) -> 0 | X13: =V13*P13/O13*0.9 -> 8228211.3 | Y13: =IF(W13=0, X13, W13) -> 8228211.3 | Z13: {=_xlfn.XLOOKUP( A13, Parcels!A:A, Parcels!AL:AL)} -> 0.0118738 | AA13: =W13*Z13 -> 0 | AB13: =Y13*Z13 -> 97700.135 | AJ13: =if(F13="CMFA", if(O13<16,10000,O13*600),if(F13="CSCDA",if(33<O13<300, O13*600,if(O13>300,(180000+(O13-300)*300),20000)))) -> 136200 | AK13: =if(F13="CMFA", if(O13<26,4000,O13*150),if(F13="CSCDA",if(33<O13<300, O13*150,if(O13>300,(45000+(O13-300)*75),5000)))) -> 34050 | AL13: =if(AE13="YES",0,IF(AND(I13>=DATE(2022,7,1),I13<=DATE(2023,6,30)),3,IF(AND(I13>=DATE(2023,7,1),I13<=DATE(2024,6,30)),2,IF(AND(I13>=DATE(2024,7,1),I13<=DATE(2025,6,30)),1,IF(AND(I13>=DATE(2025,7,1),I13<=DATE(2026,6,30)),0,"-"))))) -> 2 | AM13: =AK13*AL13 -> 68100 | AN13: {=_xlfn.xlookup(C13,'SCC Certificate Review'!C:C,'SCC Certificate Review'!F:F)}
A14: 10 | B14: 7518 Hoover St. Apartments | C14: BIF NON OZ 7518 S Hoover St, LP | D14: Los Angeles | E14: Los Angeles | F14: CMFA | G14: Grant up to $10,000 | H14: 24-041 | I14: 45324 | K14: SoLa Impact, LLC | L14: Black Impact Group | M14: Housing on Merit | N14: FALSE | O14: 79 | P14: 48 | Q14: =P14/O14 -> 0.60759494 | R14: 7518 S. Hoover, Los Angeles, CA 90044 | S14: 11850 | T14: =COUNTIF(Parcels!A:A, A14) > 0 -> TRUE | U14: =MAXIFS(Parcels!AC:AC, Parcels!A:A, A14) > 0 -> FALSE | V14: =SUMIF(Parcels!A:A, A14, Parcels!Z:Z) -> 2856000 | W14: =SUMIF(Parcels!$A:$A, $A14, Parcels!AC:AC) -> 0 | X14: =V14*P14/O14*0.9 -> 1561762 | Y14: =IF(W14=0, X14, W14) -> 1561762 | Z14: {=_xlfn.XLOOKUP( A14, Parcels!A:A, Parcels!AL:AL)} -> 0.0118738 | AA14: =W14*Z14 -> 0 | AB14: =Y14*Z14 -> 18544.05 | AJ14: =if(F14="CMFA", if(O14<16,10000,O14*600),if(F14="CSCDA",if(33<O14<300, O14*600,if(O14>300,(180000+(O14-300)*300),20000)))) -> 47400 | AK14: =if(F14="CMFA", if(O14<26,4000,O14*150),if(F14="CSCDA",if(33<O14<300, O14*150,if(O14>300,(45000+(O14-300)*75),5000)))) -> 11850 | AL14: =if(AE14="YES",0,IF(AND(I14>=DATE(2022,7,1),I14<=DATE(2023,6,30)),3,IF(AND(I14>=DATE(2023,7,1),I14<=DATE(2024,6,30)),2,IF(AND(I14>=DATE(2024,7,1),I14<=DATE(2025,6,30)),1,IF(AND(I14>=DATE(2025,7,1),I14<=DATE(2026,6,30)),0,"-"))))) -> 2 | AM14: =AK14*AL14 -> 23700 | AN14: {=_xlfn.xlookup(C14,'SCC Certificate Review'!C:C,'SCC Certificate Review'!F:F)} -> TRUE
A15: 11 | B15: 820 MacArthur Apartments | C15: 2019 Ozone Affordable Housing | D15: Oakland | E15: Alameda | F15: CMFA | G15: Grant up to $10,000 | H15: 24-052 | I15: 45345 | K15: Riaz, Inc. | M15: AOF Pacific | N15: FALSE | O15: 166 | P15: 166 | R15: 820 W MacArthur Blvd, Oakland, CA 94608 | S15: 24900 | T15: =COUNTIF(Parcels!A:A, A15) > 0 -> TRUE | U15: =MAXIFS(Parcels!AC:AC, Parcels!A:A, A15) > 0 -> TRUE | V15: =SUMIF(Parcels!A:A, A15, Parcels!Z:Z) -> 2013882 | W15: =SUMIF(Parcels!$A:$A, $A15, Parcels!AC:AC) -> 7089890 | X15: =V15*P15/O15*0.9 -> 1812493.8 | Y15: =IF(W15=0, X15, W15) -> 7089890 | Z15: {=_xlfn.XLOOKUP( A15, Parcels!A:A, Parcels!AL:AL)} -> 0.012779 | AA15: =W15*Z15 -> 90601.704 | AB15: =Y15*Z15 -> 90601.704 | AE15: YES | AJ15: =if(F15="CMFA", if(O15<16,10000,O15*600),if(F15="CSCDA",if(33<O15<300, O15*600,if(O15>300,(180000+(O15-300)*300),20000)))) -> 99600 | AK15: =if(F15="CMFA", if(O15<26,4000,O15*150),if(F15="CSCDA",if(33<O15<300, O15*150,if(O15>300,(45000+(O15-300)*75),5000)))) -> 24900 | AL15: =if(AE15="YES",0,IF(AND(I15>=DATE(2022,7,1),I15<=DATE(2023,6,30)),3,IF(AND(I15>=DATE(2023,7,1),I15<=DATE(2024,6,30)),2,IF(AND(I15>=DATE(2024,7,1),I15<=DATE(2025,6,30)),1,IF(AND(I15>=DATE(2025,7,1),I15<=DATE(2026,6,30)),0,"-"))))) -> 0 | AM15: =AK15*AL15 -> 0 | AN15: {=_xlfn.xlookup(C15,'SCC Certificate Review'!C:C,'SCC Certificate Review'!F:F)} -> TRUE
A16: 12 | B16: The Waterloo Apartments | C16: 801 Waterloo Partners, LP | D16: Los Angeles | E16: Los Angeles | F16: CMFA | G16: Grant up to $10,000 | H16: 24-053 | I16: 45345 | K16: The Greg Scott Company | M16: Kingdom Development, Inc. | N16: FALSE | O16: 154 | P16: 154 | Q16: =P16/O16 -> 1 | R16: 801-809 Waterloo Street, Los Angeles, CA | S16: 23250 | T16: =COUNTIF(Parcels!A:A, A16) > 0 -> TRUE | U16: =MAXIFS(Parcels!AC:AC, Parcels!A:A, A16) > 0 -> FALSE | V16: =SUMIF(Parcels!A:A, A16, Parcels!Z:Z) -> 1360000 | W16: =SUMIF(Parcels!$A:$A, $A16, Parcels!AC:AC) -> 0 | X16: =V16*P16/O16*0.9 -> 1224000 | Y16: =IF(W16=0, X16, W16) -> 1224000 | Z16: {=_xlfn.XLOOKUP( A16, Parcels!A:A, Parcels!AL:AL)} -> 0.0118738 | AA16: =W16*Z16 -> 0 | AB16: =Y16*Z16 -> 14533.531 | AJ16: =if(F16="CMFA", if(O16<16,10000,O16*600),if(F16="CSCDA",if(33<O16<300, O16*600,if(O16>300,(180000+(O16-300)*300),20000)))) -> 92400 | AK16: =if(F16="CMFA", if(O16<26,4000,O16*150),if(F16="CSCDA",if(33<O16<300, O16*150,if(O16>300,(45000+(O16-300)*75),5000)))) -> 23100 | AL16: =if(AE16="YES",0,IF(AND(I16>=DATE(2022,7,1),I16<=DATE(2023,6,30)),3,IF(AND(I16>=DATE(2023,7,1),I16<=DATE(2024,6,30)),2,IF(AND(I16>=DATE(2024,7,1),I16<=DATE(2025,6,30)),1,IF(AND(I16>=DATE(2025,7,1),I16<=DATE(2026,6,30)),0,"-"))))) -> 2 | AM16: =AK16*AL16 -> 46200 | AN16: {=_xlfn.xlookup(C16,'SCC Certificate Review'!C:C,'SCC Certificate Review'!F:F)} -> TRUE
A17: 14 | B17: Electric Lofts Apartments | C17: Electric Lofts, LP | D17: Oakland | E17: Alameda | F17: CMFA | G17: Grant up to $10,000 | H17: 24-074 | I17: 45366 | K17: Trestle Development LLC | M17: AOF / Pacific Affordable Housing Corp | N17: FALSE | O17: 89 | P17: 40 | R17: 2415 Valdez St, Oakland, CA 94612 | S17: 13350 | T17: =COUNTIF(Parcels!A:A, A17) > 0 -> TRUE | U17: =MAXIFS(Parcels!AC:AC, Parcels!A:A, A17) > 0 -> FALSE | V17: =SUMIF(Parcels!A:A, A17, Parcels!Z:Z) -> 24257157 | W17: =SUMIF(Parcels!$A:$A, $A17, Parcels!AC:AC) -> 0 | X17: =V17*P17/O17*0.9 -> 9811883.7 | Y17: =IF(W17=0, X17, W17) -> 9811883.7 | Z17: {=_xlfn.XLOOKUP( A17, Parcels!A:A, Parcels!AL:AL)} -> 0.012779 | AA17: =W17*Z17 -> 0 | AB17: =Y17*Z17 -> 125386.06 | AD17: https://www.electriclofts.com/ | AJ17: =if(F17="CMFA", if(O17<16,10000,O17*600),if(F17="CSCDA",if(33<O17<300, O17*600,if(O17>300,(180000+(O17-300)*300),20000)))) -> 53400 | AK17: =if(F17="CMFA", if(O17<26,4000,O17*150),if(F17="CSCDA",if(33<O17<300, O17*150,if(O17>300,(45000+(O17-300)*75),5000)))) -> 13350 | AL17: =if(AE17="YES",0,IF(AND(I17>=DATE(2022,7,1),I17<=DATE(2023,6,30)),3,IF(AND(I17>=DATE(2023,7,1),I17<=DATE(2024,6,30)),2,IF(AND(I17>=DATE(2024,7,1),I17<=DATE(2025,6,30)),1,IF(AND(I17>=DATE(2025,7,1),I17<=DATE(2026,6,30)),0,"-"))))) -> 2 | AM17: =AK17*AL17 -> 26700 | AN17: {=_xlfn.xlookup(C17,'SCC Certificate Review'!C:C,'SCC Certificate Review'!F:F)} -> TRUE
A18: 13 | B18: 275 Turk Street Apartments | C18: RHI-Mosser 275 Turk LP | D18: San Francisco | E18: San Francisco | F18: CMFA | G18: Grant up to $10,000 | H18: 24-076 | I18: 45366 | J18: TRUE | K18: Mosser Capital, LLC | L18: Stars Real Estate Investment | M18: Kingdom Development, Inc. | N18: FALSE | O18: 66 | P18: 27 | R18: 275 Turk St, San Francisco, CA | S18: 9900 | T18: =COUNTIF(Parcels!A:A, A18) > 0 -> TRUE | U18: =MAXIFS(Parcels!AC:AC, Parcels!A:A, A18) > 0 -> FALSE | V18: =SUMIF(Parcels!A:A, A18, Parcels!Z:Z) -> 17116303 | W18: =SUMIF(Parcels!$A:$A, $A18, Parcels!AC:AC) -> 0 | X18: =V18*P18/O18*0.9 -> 6301911.6 | Y18: =IF(W18=0, X18, W18) -> 6301911.6 | Z18: {=_xlfn.XLOOKUP( A18, Parcels!A:A, Parcels!AL:AL)} -> 0.012 | AA18: =W18*Z18 -> 0 | AB18: =Y18*Z18 -> 75622.939 | AJ18: =if(F18="CMFA", if(O18<16,10000,O18*600),if(F18="CSCDA",if(33<O18<300, O18*600,if(O18>300,(180000+(O18-300)*300),20000)))) -> 39600 | AK18: =if(F18="CMFA", if(O18<26,4000,O18*150),if(F18="CSCDA",if(33<O18<300, O18*150,if(O18>300,(45000+(O18-300)*75),5000)))) -> 9900 | AL18: =if(AE18="YES",0,IF(AND(I18>=DATE(2022,7,1),I18<=DATE(2023,6,30)),3,IF(AND(I18>=DATE(2023,7,1),I18<=DATE(2024,6,30)),2,IF(AND(I18>=DATE(2024,7,1),I18<=DATE(2025,6,30)),1,IF(AND(I18>=DATE(2025,7,1),I18<=DATE(2026,6,30)),0,"-"))))) -> 2 | AM18: =AK18*AL18 -> 19800 | AN18: {=_xlfn.xlookup(C18,'SCC Certificate Review'!C:C,'SCC Certificate Review'!F:F)}
A19: 15 | B19: Premiere Hollywood Apartments | C19: OODB2, LP | D19: Los Angeles | E19: Los Angeles | F19: CMFA | G19: Grant up to $10,000 | H19: 24-178 | I19: 45408 | J19: TRUE | K19: Housing Diversity Corporation | M19: PEP Housing | N19: FALSE | O19: 69 | P19: 69 | Q19: =P19/O19 -> 1 | R19: 6762 Hawthorn Ave, Los Angeles, CA 90028 | S19: 10350 | T19: =COUNTIF(Parcels!A:A, A19) > 0 -> TRUE | U19: =MAXIFS(Parcels!AC:AC, Parcels!A:A, A19) > 0 -> FALSE | V19: =SUMIF(Parcels!A:A, A19, Parcels!Z:Z) -> 8706757 | W19: =SUMIF(Parcels!$A:$A, $A19, Parcels!AC:AC) -> 0 | X19: =V19*P19/O19*0.9 -> 7836081.3 | Y19: =IF(W19=0, X19, W19) -> 7836081.3 | Z19: {=_xlfn.XLOOKUP( A19, Parcels!A:A, Parcels!AL:AL)} -> 0.0118738 | AA19: =W19*Z19 -> 0 | AB19: =Y19*Z19 -> 93044.062 | AF19: 2023 | AJ19: =if(F19="CMFA", if(O19<16,10000,O19*600),if(F19="CSCDA",if(33<O19<300, O19*600,if(O19>300,(180000+(O19-300)*300),20000)))) -> 41400 | AK19: =if(F19="CMFA", if(O19<26,4000,O19*150),if(F19="CSCDA",if(33<O19<300, O19*150,if(O19>300,(45000+(O19-300)*75),5000)))) -> 10350 | AL19: =if(AE19="YES",0,IF(AND(I19>=DATE(2022,7,1),I19<=DATE(2023,6,30)),3,IF(AND(I19>=DATE(2023,7,1),I19<=DATE(2024,6,30)),2,IF(AND(I19>=DATE(2024,7,1),I19<=DATE(2025,6,30)),1,IF(AND(I19>=DATE(2025,7,1),I19<=DATE(2026,6,30)),0,"-"))))) -> 2 | AM19: =AK19*AL19 -> 20700 | AN19: {=_xlfn.xlookup(C19,'SCC Certificate Review'!C:C,'SCC Certificate Review'!F:F)}
A20: 17 | B20: 4252 Crenshaw Apartments | C20: 4252 Crenshaw LP | D20: Los Angeles | E20: Los Angeles | F20: CMFA | G20: Grant up to $10,000 | H20: 24-199 | I20: 45429 | K20: Thrive Living | L20: Magnum Real Estate Group | M20: Kingdom Development, Inc. | N20: FALSE | O20: 111 | P20: 111 | Q20: =P20/O20 -> 1 | R20: 4252 S CRENSHAW BLVD LOS ANGELES CA 90008 | S20: 16650 | T20: =COUNTIF(Parcels!A:A, A20) > 0 -> TRUE | U20: =MAXIFS(Parcels!AC:AC, Parcels!A:A, A20) > 0 -> TRUE | V20: =SUMIF(Parcels!A:A, A20, Parcels!Z:Z) -> 26914860 | W20: =SUMIF(Parcels!$A:$A, $A20, Parcels!AC:AC) -> 26914860 | X20: =V20*P20/O20*0.9 -> 24223374 | Y20: =IF(W20=0, X20, W20) -> 26914860 | Z20: {=_xlfn.XLOOKUP( A20, Parcels!A:A, Parcels!AL:AL)} -> 0.0118738 | AA20: =W20*Z20 -> 319581.66 | AB20: =Y20*Z20 -> 319581.66 | AE20: NO | AF20: 2020 | AJ20: =if(F20="CMFA", if(O20<16,10000,O20*600),if(F20="CSCDA",if(33<O20<300, O20*600,if(O20>300,(180000+(O20-300)*300),20000)))) -> 66600 | AK20: =if(F20="CMFA", if(O20<26,4000,O20*150),if(F20="CSCDA",if(33<O20<300, O20*150,if(O20>300,(45000+(O20-300)*75),5000)))) -> 16650 | AL20: =if(AE20="YES",0,IF(AND(I20>=DATE(2022,7,1),I20<=DATE(2023,6,30)),3,IF(AND(I20>=DATE(2023,7,1),I20<=DATE(2024,6,30)),2,IF(AND(I20>=DATE(2024,7,1),I20<=DATE(2025,6,30)),1,IF(AND(I20>=DATE(2025,7,1),I20<=DATE(2026,6,30)),0,"-"))))) -> 2 | AM20: =AK20*AL20 -> 33300 | AN20: {=_xlfn.xlookup(C20,'SCC Certificate Review'!C:C,'SCC Certificate Review'!F:F)} -> TRUE
A21: 16 | B21: Montessa Apartments | C21: Affordable Housing Alliance II, Inc. dba Integrity Housing | D21: Vacaville | E21: Solano | F21: CMFA | G21: Grant up to $10,000 | H21: 24-200 | I21: 45429 | K21: Ascenda Capital | M21: Integrity Housing | N21: FALSE | O21: 169 | P21: 58 | R21: 343 Moon River Pl, Vacaville, CA 95687 | S21: 8700 | T21: =COUNTIF(Parcels!A:A, A21) > 0 -> TRUE | U21: =MAXIFS(Parcels!AC:AC, Parcels!A:A, A21) > 0 -> FALSE | V21: =SUMIF(Parcels!A:A, A21, Parcels!Z:Z) -> 1333447 | W21: =SUMIF(Parcels!$A:$A, $A21, Parcels!AC:AC) -> 0 | X21: =V21*P21/O21*0.9 -> 411869.43 | Y21: =IF(W21=0, X21, W21) -> 411869.43 | Z21: {=_xlfn.XLOOKUP( A21, Parcels!A:A, Parcels!AL:AL)} -> 0.0117033 | AA21: =W21*Z21 -> 0 | AB21: =Y21*Z21 -> 4820.2315 | AE21: YES | AJ21: =if(F21="CMFA", if(O21<16,10000,O21*600),if(F21="CSCDA",if(33<O21<300, O21*600,if(O21>300,(180000+(O21-300)*300),20000)))) -> 101400 | AK21: =if(F21="CMFA", if(O21<26,4000,O21*150),if(F21="CSCDA",if(33<O21<300, O21*150,if(O21>300,(45000+(O21-300)*75),5000)))) -> 25350 | AL21: =if(AE21="YES",0,IF(AND(I21>=DATE(2022,7,1),I21<=DATE(2023,6,30)),3,IF(AND(I21>=DATE(2023,7,1),I21<=DATE(2024,6,30)),2,IF(AND(I21>=DATE(2024,7,1),I21<=DATE(2025,6,30)),1,IF(AND(I21>=DATE(2025,7,1),I21<=DATE(2026,6,30)),0,"-"))))) -> 0 | AM21: =AK21*AL21 -> 0 | AN21: {=_xlfn.xlookup(C21,'SCC Certificate Review'!C:C,'SCC Certificate Review'!F:F)}
A22: 18 | B22: Fallbrook Trail Apartments | C22: 1735 South Mission LP | D22: San Diego | E22: San Diego | F22: CMFA | G22: Grant up to $10,000 | H22: 24-219 | I22: 45450 | K22: AOF | L22: Pacific Affordable Housing Corp | M22: Pacific Affordable Housing Corp | N22: FALSE | O22: 103 | P22: 102 | R22: 1735 S Mission Rd, Fallbrook, CA 92028 | S22: 15300 | T22: =COUNTIF(Parcels!A:A, A22) > 0 -> TRUE | U22: =MAXIFS(Parcels!AC:AC, Parcels!A:A, A22) > 0 -> FALSE | V22: =SUMIF(Parcels!A:A, A22, Parcels!Z:Z) -> 32460480 | W22: =SUMIF(Parcels!$A:$A, $A22, Parcels!AC:AC) -> 0 | X22: =V22*P22/O22*0.9 -> 28930797 | Y22: =IF(W22=0, X22, W22) -> 28930797 | Z22: {=_xlfn.XLOOKUP( A22, Parcels!A:A, Parcels!AL:AL)} -> 0.010783 | AA22: =W22*Z22 -> 0 | AB22: =Y22*Z22 -> 311960.78 | AF22: 2021 | AJ22: =if(F22="CMFA", if(O22<16,10000,O22*600),if(F22="CSCDA",if(33<O22<300, O22*600,if(O22>300,(180000+(O22-300)*300),20000)))) -> 61800 | AK22: =if(F22="CMFA", if(O22<26,4000,O22*150),if(F22="CSCDA",if(33<O22<300, O22*150,if(O22>300,(45000+(O22-300)*75),5000)))) -> 15450 | AL22: =if(AE22="YES",0,IF(AND(I22>=DATE(2022,7,1),I22<=DATE(2023,6,30)),3,IF(AND(I22>=DATE(2023,7,1),I22<=DATE(2024,6,30)),2,IF(AND(I22>=DATE(2024,7,1),I22<=DATE(2025,6,30)),1,IF(AND(I22>=DATE(2025,7,1),I22<=DATE(2026,6,30)),0,"-"))))) -> 2 | AM22: =AK22*AL22 -> 30900 | AN22: {=_xlfn.xlookup(C22,'SCC Certificate Review'!C:C,'SCC Certificate Review'!F:F)} -> TRUE
A23: 20 | B23: Pinetree Terrace Apartments | C23: Hacienda Investors LP | D23: Los Angeles | E23: Los Angeles | F23: CMFA | G23: Grant up to $10,000 | H23: 24-220 | I23: 45450 | K23: GHC Housing Partners | M23: Foundation for Affordable Housing | N23: FALSE | O23: 58 | P23: 58 | Q23: =P23/O23 -> 1 | R23: 7940 Reseda Boulevard, Reseda, CA | S23: 8700 | T23: =COUNTIF(Parcels!A:A, A23) > 0 -> TRUE | U23: =MAXIFS(Parcels!AC:AC, Parcels!A:A, A23) > 0 -> TRUE | V23: =SUMIF(Parcels!A:A, A23, Parcels!Z:Z) -> 17952000 | W23: =SUMIF(Parcels!$A:$A, $A23, Parcels!AC:AC) -> 15786989 | X23: =V23*P23/O23*0.9 -> 16156800 | Y23: =IF(W23=0, X23, W23) -> 15786989 | Z23: {=_xlfn.XLOOKUP( A23, Parcels!A:A, Parcels!AL:AL)} -> 0.0118738 | AA23: =W23*Z23 -> 187451.55 | AB23: =Y23*Z23 -> 187451.55 | AG23: 17600000 | AH23: 45471 | AJ23: =if(F23="CMFA", if(O23<16,10000,O23*600),if(F23="CSCDA",if(33<O23<300, O23*600,if(O23>300,(180000+(O23-300)*300),20000)))) -> 34800 | AK23: =if(F23="CMFA", if(O23<26,4000,O23*150),if(F23="CSCDA",if(33<O23<300, O23*150,if(O23>300,(45000+(O23-300)*75),5000)))) -> 8700 | AL23: =if(AE23="YES",0,IF(AND(I23>=DATE(2022,7,1),I23<=DATE(2023,6,30)),3,IF(AND(I23>=DATE(2023,7,1),I23<=DATE(2024,6,30)),2,IF(AND(I23>=DATE(2024,7,1),I23<=DATE(2025,6,30)),1,IF(AND(I23>=DATE(2025,7,1),I23<=DATE(2026,6,30)),0,"-"))))) -> 2 | AM23: =AK23*AL23 -> 17400 | AN23: {=_xlfn.xlookup(C23,'SCC Certificate Review'!C:C,'SCC Certificate Review'!F:F)} -> TRUE
A24: 21 | B24: Windmere Court Apartments | C24: Hacienda Investors LP | D24: Los Angeles | E24: Los Angeles | F24: CMFA | G24: Grant up to $10,000 | H24: 24-221 | I24: 45450 | K24: GHC Housing Partners | M24: Foundation for Affordable Housing | N24: FALSE | O24: 52 | P24: 52 | Q24: =P24/O24 -> 1 | R24: 18325 Saticoy St, Reseda, CA 91335 | S24: 7800 | T24: =COUNTIF(Parcels!A:A, A24) > 0 -> TRUE | U24: =MAXIFS(Parcels!AC:AC, Parcels!A:A, A24) > 0 -> TRUE | V24: =SUMIF(Parcels!A:A, A24, Parcels!Z:Z) -> 16626000 | W24: =SUMIF(Parcels!$A:$A, $A24, Parcels!AC:AC) -> 16306781 | X24: =V24*P24/O24*0.9 -> 14963400 | Y24: =IF(W24=0, X24, W24) -> 16306781 | Z24: {=_xlfn.XLOOKUP( A24, Parcels!A:A, Parcels!AL:AL)} -> 0.0118738 | AA24: =W24*Z24 -> 193623.46 | AB24: =Y24*Z24 -> 193623.46 | AG24: 16300000 | AH24: 45456 | AJ24: =if(F24="CMFA", if(O24<16,10000,O24*600),if(F24="CSCDA",if(33<O24<300, O24*600,if(O24>300,(180000+(O24-300)*300),20000)))) -> 31200 | AK24: =if(F24="CMFA", if(O24<26,4000,O24*150),if(F24="CSCDA",if(33<O24<300, O24*150,if(O24>300,(45000+(O24-300)*75),5000)))) -> 7800 | AL24: =if(AE24="YES",0,IF(AND(I24>=DATE(2022,7,1),I24<=DATE(2023,6,30)),3,IF(AND(I24>=DATE(2023,7,1),I24<=DATE(2024,6,30)),2,IF(AND(I24>=DATE(2024,7,1),I24<=DATE(2025,6,30)),1,IF(AND(I24>=DATE(2025,7,1),I24<=DATE(2026,6,30)),0,"-"))))) -> 2 | AM24: =AK24*AL24 -> 15600 | AN24: {=_xlfn.xlookup(C24,'SCC Certificate Review'!C:C,'SCC Certificate Review'!F:F)} -> TRUE
A25: 19 | B25: The Arbors Apartments | C25: Post Arbors Santa Ana LP | D25: Santa Ana | E25: Orange | F25: CMFA | G25: Grant up to $10,000 | H25: 24-222 | I25: 45450 | K25: Ascenda Capital | L25: Post Investment Group | M25: Integrity Housing | N25: FALSE | O25: 160 | P25: 160 | R25: 1100-1200 E. Fairhaven Avenue, Santa Ana, CA | S25: 24000 | T25: =COUNTIF(Parcels!A:A, A25) > 0 -> TRUE | U25: =MAXIFS(Parcels!AC:AC, Parcels!A:A, A25) > 0 -> FALSE | V25: =SUMIF(Parcels!A:A, A25, Parcels!Z:Z) -> 40750000 | W25: =SUMIF(Parcels!$A:$A, $A25, Parcels!AC:AC) -> 0 | X25: =V25*P25/O25*0.9 -> 36675000 | Y25: =IF(W25=0, X25, W25) -> 36675000 | Z25: {=_xlfn.XLOOKUP( A25, Parcels!A:A, Parcels!AL:AL)} -> 0.011195 | AA25: =W25*Z25 -> 0 | AB25: =Y25*Z25 -> 410576.62 | AF25: 1969 | AJ25: =if(F25="CMFA", if(O25<16,10000,O25*600),if(F25="CSCDA",if(33<O25<300, O25*600,if(O25>300,(180000+(O25-300)*300),20000)))) -> 96000 | AK25: =if(F25="CMFA", if(O25<26,4000,O25*150),if(F25="CSCDA",if(33<O25<300, O25*150,if(O25>300,(45000+(O25-300)*75),5000)))) -> 24000 | AL25: =if(AE25="YES",0,IF(AND(I25>=DATE(2022,7,1),I25<=DATE(2023,6,30)),3,IF(AND(I25>=DATE(2023,7,1),I25<=DATE(2024,6,30)),2,IF(AND(I25>=DATE(2024,7,1),I25<=DATE(2025,6,30)),1,IF(AND(I25>=DATE(2025,7,1),I25<=DATE(2026,6,30)),0,"-"))))) -> 2 | AM25: =AK25*AL25 -> 48000 | AN25: {=_xlfn.xlookup(C25,'SCC Certificate Review'!C:C,'SCC Certificate Review'!F:F)} -> TRUE
A26: 22 | B26: Seville Gardens Apartments | C26: BG Apartments Investors LP | D26: Huntington Park | E26: Los Angeles | F26: CMFA | G26: Grant up to $10,000 | H26: 24-223 | I26: 45450 | K26: GHC Housing Partners | M26: Foundation for Affordable Housing | N26: FALSE | O26: 225 | P26: 225 | Q26: =P26/O26 -> 1 | R26: 2701 Randolph St., Huntington Park, CA | S26: 33750 | T26: =COUNTIF(Parcels!A:A, A26) > 0 -> TRUE | U26: =MAXIFS(Parcels!AC:AC, Parcels!A:A, A26) > 0 -> TRUE | V26: =SUMIF(Parcels!A:A, A26, Parcels!Z:Z) -> 34425000 | W26: =SUMIF(Parcels!$A:$A, $A26, Parcels!AC:AC) -> 31825913 | X26: =V26*P26/O26*0.9 -> 30982500 | Y26: =IF(W26=0, X26, W26) -> 31825913 | Z26: {=_xlfn.XLOOKUP( A26, Parcels!A:A, Parcels!AL:AL)} -> 0.01385148 | AA26: =W26*Z26 -> 440836 | AB26: =Y26*Z26 -> 440836 | AF26: 1989 | AJ26: =if(F26="CMFA", if(O26<16,10000,O26*600),if(F26="CSCDA",if(33<O26<300, O26*600,if(O26>300,(180000+(O26-300)*300),20000)))) -> 135000 | AK26: =if(F26="CMFA", if(O26<26,4000,O26*150),if(F26="CSCDA",if(33<O26<300, O26*150,if(O26>300,(45000+(O26-300)*75),5000)))) -> 33750 | AL26: =if(AE26="YES",0,IF(AND(I26>=DATE(2022,7,1),I26<=DATE(2023,6,30)),3,IF(AND(I26>=DATE(2023,7,1),I26<=DATE(2024,6,30)),2,IF(AND(I26>=DATE(2024,7,1),I26<=DATE(2025,6,30)),1,IF(AND(I26>=DATE(2025,7,1),I26<=DATE(2026,6,30)),0,"-"))))) -> 2 | AM26: =AK26*AL26 -> 67500 | AN26: {=_xlfn.xlookup(C26,'SCC Certificate Review'!C:C,'SCC Certificate Review'!F:F)} -> TRUE
A27: 23 | B27: Harbour Residences Apartments | C27: RMG Fee Avalon, LP | D27: Los Angeles | E27: Los Angeles | F27: CMFA | G27: Grant up to $10,000 | H27: 24-252 | I27: 45492 | J27: TRUE | K27: RMG Housing | M27: DECRO Corporation | N27: FALSE | O27: 74 | P27: 74 | Q27: =P27/O27 -> 1 | R27: 445 N. Avalon Boulevard, Los Angeles, CA | S27: 11100 | T27: =COUNTIF(Parcels!A:A, A27) > 0 -> TRUE | U27: =MAXIFS(Parcels!AC:AC, Parcels!A:A, A27) > 0 -> FALSE | V27: =SUMIF(Parcels!A:A, A27, Parcels!Z:Z) -> 8899678 | W27: =SUMIF(Parcels!$A:$A, $A27, Parcels!AC:AC) -> 0 | X27: =V27*P27/O27*0.9 -> 8009710.2 | Y27: =IF(W27=0, X27, W27) -> 8009710.2 | Z27: {=_xlfn.XLOOKUP( A27, Parcels!A:A, Parcels!AL:AL)} -> 0.0118738 | AA27: =W27*Z27 -> 0 | AB27: =Y27*Z27 -> 95105.697 | AE27: YES | AJ27: =if(F27="CMFA", if(O27<16,10000,O27*600),if(F27="CSCDA",if(33<O27<300, O27*600,if(O27>300,(180000+(O27-300)*300),20000)))) -> 44400 | AK27: =if(F27="CMFA", if(O27<26,4000,O27*150),if(F27="CSCDA",if(33<O27<300, O27*150,if(O27>300,(45000+(O27-300)*75),5000)))) -> 11100 | AL27: =if(AE27="YES",0,IF(AND(I27>=DATE(2022,7,1),I27<=DATE(2023,6,30)),3,IF(AND(I27>=DATE(2023,7,1),I27<=DATE(2024,6,30)),2,IF(AND(I27>=DATE(2024,7,1),I27<=DATE(2025,6,30)),1,IF(AND(I27>=DATE(2025,7,1),I27<=DATE(2026,6,30)),0,"-"))))) -> 0 | AM27: =AK27*AL27 -> 0 | AN27: {=_xlfn.xlookup(C27,'SCC Certificate Review'!C:C,'SCC Certificate Review'!F:F)}
A28: 24 | B28: 4209 Western Avenue Apartments | C28: BIF NON OZ 4209 WESTERN AVE, LP | D28: Los Angeles | E28: Los Angeles | F28: CMFA | G28: Grant up to $10,000 | H28: 24-253 | I28: 45492 | K28: SoLa Impact, LLC | M28: Housing on Merit | N28: FALSE | O28: 25 | P28: 24 | Q28: =P28/O28 -> 0.96 | R28: 4209 S Western Ave, Los Angeles, CA 90062 | S28: 3600 | T28: =COUNTIF(Parcels!A:A, A28) > 0 -> TRUE | U28: =MAXIFS(Parcels!AC:AC, Parcels!A:A, A28) > 0 -> TRUE | V28: =SUMIF(Parcels!A:A, A28, Parcels!Z:Z) -> 10924200 | W28: =SUMIF(Parcels!$A:$A, $A28, Parcels!AC:AC) -> 10903361 | X28: =V28*P28/O28*0.9 -> 9438508.8 | Y28: =IF(W28=0, X28, W28) -> 10903361 | Z28: {=_xlfn.XLOOKUP( A28, Parcels!A:A, Parcels!AL:AL)} -> 0.0118738 | AA28: =W28*Z28 -> 129464.33 | AB28: =Y28*Z28 -> 129464.33 | AJ28: =if(F28="CMFA", if(O28<16,10000,O28*600),if(F28="CSCDA",if(33<O28<300, O28*600,if(O28>300,(180000+(O28-300)*300),20000)))) -> 15000 | AK28: =if(F28="CMFA", if(O28<26,4000,O28*150),if(F28="CSCDA",if(33<O28<300, O28*150,if(O28>300,(45000+(O28-300)*75),5000)))) -> 4000 | AL28: =if(AE28="YES",0,IF(AND(I28>=DATE(2022,7,1),I28<=DATE(2023,6,30)),3,IF(AND(I28>=DATE(2023,7,1),I28<=DATE(2024,6,30)),2,IF(AND(I28>=DATE(2024,7,1),I28<=DATE(2025,6,30)),1,IF(AND(I28>=DATE(2025,7,1),I28<=DATE(2026,6,30)),0,"-"))))) -> 1 | AM28: =AK28*AL28 -> 4000 | AN28: {=_xlfn.xlookup(C28,'SCC Certificate Review'!C:C,'SCC Certificate Review'!F:F)} -> TRUE
A29: 25 | B29: 1130 Martin Luther King Jr. Blvd Apartments | C29: BIF NON OZ 1100 MLK BLK, LP | D29: Los Angeles | E29: Los Angeles | F29: CMFA | H29: 24-254 | I29: 45492 | K29: SoLa Impact, LLC | M29: Housing on Merit | N29: FALSE | O29: 29 | P29: 28 | Q29: =P29/O29 -> 0.96551724 | R29: 1130 W Martin Luther King Jr Blvd, Los Angeles, CA 90037 | S29: 4200 | T29: =COUNTIF(Parcels!A:A, A29) > 0 -> TRUE | U29: =MAXIFS(Parcels!AC:AC, Parcels!A:A, A29) > 0 -> TRUE | V29: =SUMIF(Parcels!A:A, A29, Parcels!Z:Z) -> 12796920 | W29: =SUMIF(Parcels!$A:$A, $A29, Parcels!AC:AC) -> 12776081 | X29: =V29*P29/O29*0.9 -> 11120082 | Y29: =IF(W29=0, X29, W29) -> 12776081 | Z29: {=_xlfn.XLOOKUP( A29, Parcels!A:A, Parcels!AL:AL)} -> 0.0118738 | AA29: =W29*Z29 -> 151700.63 | AB29: =Y29*Z29 -> 151700.63 | AJ29: =if(F29="CMFA", if(O29<16,10000,O29*600),if(F29="CSCDA",if(33<O29<300, O29*600,if(O29>300,(180000+(O29-300)*300),20000)))) -> 17400 | AK29: =if(F29="CMFA", if(O29<26,4000,O29*150),if(F29="CSCDA",if(33<O29<300, O29*150,if(O29>300,(45000+(O29-300)*75),5000)))) -> 4350 | AL29: =if(AE29="YES",0,IF(AND(I29>=DATE(2022,7,1),I29<=DATE(2023,6,30)),3,IF(AND(I29>=DATE(2023,7,1),I29<=DATE(2024,6,30)),2,IF(AND(I29>=DATE(2024,7,1),I29<=DATE(2025,6,30)),1,IF(AND(I29>=DATE(2025,7,1),I29<=DATE(2026,6,30)),0,"-"))))) -> 1 | AM29: =AK29*AL29 -> 4350 | AN29: {=_xlfn.xlookup(C29,'SCC Certificate Review'!C:C,'SCC Certificate Review'!F:F)} -> TRUE
A30: 34 | B30: Appian Terrace Apartments | C30: APPIAN LP | D30: El Sobrante | E30: Contra Costa | F30: CMFA | G30: Grant up to $10,000 | H30: 24-277 | I30: 45513 | K30: Tesseract Capital Group | M30: Housing on Merit | N30: FALSE | O30: 41 | P30: 41 | R30: 4481 Appian Way, El Sobrante, CA 94803 | S30: 6150 | T30: =COUNTIF(Parcels!A:A, A30) > 0 -> TRUE | U30: =MAXIFS(Parcels!AC:AC, Parcels!A:A, A30) > 0 -> FALSE | V30: =SUMIF(Parcels!A:A, A30, Parcels!Z:Z) -> 9977564 | W30: =SUMIF(Parcels!$A:$A, $A30, Parcels!AC:AC) -> 0 | X30: =V30*P30/O30*0.9 -> 8979807.6 | Y30: =IF(W30=0, X30, W30) -> 8979807.6 | Z30: {=_xlfn.XLOOKUP( A30, Parcels!A:A, Parcels!AL:AL)} -> 0.012792 | AA30: =W30*Z30 -> 0 | AB30: =Y30*Z30 -> 114869.7 | AJ30: =if(F30="CMFA", if(O30<16,10000,O30*600),if(F30="CSCDA",if(33<O30<300, O30*600,if(O30>300,(180000+(O30-300)*300),20000)))) -> 24600 | AK30: =if(F30="CMFA", if(O30<26,4000,O30*150),if(F30="CSCDA",if(33<O30<300, O30*150,if(O30>300,(45000+(O30-300)*75),5000)))) -> 6150 | AL30: =if(AE30="YES",0,IF(AND(I30>=DATE(2022,7,1),I30<=DATE(2023,6,30)),3,IF(AND(I30>=DATE(2023,7,1),I30<=DATE(2024,6,30)),2,IF(AND(I30>=DATE(2024,7,1),I30<=DATE(2025,6,30)),1,IF(AND(I30>=DATE(2025,7,1),I30<=DATE(2026,6,30)),0,"-"))))) -> 1 | AM30: =AK30*AL30 -> 6150 | AN30: {=_xlfn.xlookup(C30,'SCC Certificate Review'!C:C,'SCC Certificate Review'!F:F)} -> TRUE
A31: 35 | B31: Sierra Park Apartments | C31: Sierra Park LP, a California Limited Partnership | D31: Unincorporated | E31: Sacramento | F31: CMFA | G31: Grant up to $10,000 | H31: 24-278 | I31: 45513 | K31: Tesseract Capital Group | M31: Housing on Merit | N31: FALSE | O31: 104 | P31: 104 | R31: 4930 Polk St, North Highlands, CA 95660 | S31: 15600 | T31: =COUNTIF(Parcels!A:A, A31) > 0 -> TRUE | U31: =MAXIFS(Parcels!AC:AC, Parcels!A:A, A31) > 0 -> TRUE | V31: =SUMIF(Parcels!A:A, A31, Parcels!Z:Z) -> 25646900 | W31: =SUMIF(Parcels!$A:$A, $A31, Parcels!AC:AC) -> 23179668 | X31: =V31*P31/O31*0.9 -> 23082210 | Y31: =IF(W31=0, X31, W31) -> 23179668 | Z31: {=_xlfn.XLOOKUP( A31, Parcels!A:A, Parcels!AL:AL)} -> 0.011785 | AA31: =W31*Z31 -> 273172.39 | AB31: =Y31*Z31 -> 273172.39 | AJ31: =if(F31="CMFA", if(O31<16,10000,O31*600),if(F31="CSCDA",if(33<O31<300, O31*600,if(O31>300,(180000+(O31-300)*300),20000)))) -> 62400 | AK31: =if(F31="CMFA", if(O31<26,4000,O31*150),if(F31="CSCDA",if(33<O31<300, O31*150,if(O31>300,(45000+(O31-300)*75),5000)))) -> 15600 | AL31: =if(AE31="YES",0,IF(AND(I31>=DATE(2022,7,1),I31<=DATE(2023,6,30)),3,IF(AND(I31>=DATE(2023,7,1),I31<=DATE(2024,6,30)),2,IF(AND(I31>=DATE(2024,7,1),I31<=DATE(2025,6,30)),1,IF(AND(I31>=DATE(2025,7,1),I31<=DATE(2026,6,30)),0,"-"))))) -> 1 | AM31: =AK31*AL31 -> 15600 | AN31: {=_xlfn.xlookup(C31,'SCC Certificate Review'!C:C,'SCC Certificate Review'!F:F)} -> TRUE
A32: 33 | B32: 7524 S. Hoover St. Apartments | C32: BIF NON OZ 7524 S HOOVER ST, LP | D32: Los Angeles | E32: Los Angeles | F32: CMFA | G32: Grant up to $10,000 | H32: 24-279 | I32: 45513 | K32: SoLa Impact, LLC | M32: Housing on Merit | N32: TRUE | O32: 79 | P32: 48 | Q32: =P32/O32 -> 0.60759494 | R32: 7518 S. Hoover, Los Angeles, CA | S32: 11850 | T32: =COUNTIF(Parcels!A:A, A32) > 0 -> TRUE | U32: =MAXIFS(Parcels!AC:AC, Parcels!A:A, A32) > 0 -> FALSE | V32: =SUMIF(Parcels!A:A, A32, Parcels!Z:Z) -> 0 | W32: =SUMIF(Parcels!$A:$A, $A32, Parcels!AC:AC) -> 0 | X32: =V32*P32/O32*0.9 -> 0 | Y32: =IF(W32=0, X32, W32) -> 0 | Z32: {=_xlfn.XLOOKUP( A32, Parcels!A:A, Parcels!AL:AL)} -> 0.0118738 | AA32: =W32*Z32 -> 0 | AB32: =Y32*Z32 -> 0 | AE32: YES | AJ32: =if(F32="CMFA", if(O32<16,10000,O32*600),if(F32="CSCDA",if(33<O32<300, O32*600,if(O32>300,(180000+(O32-300)*300),20000)))) -> 47400 | AK32: =if(F32="CMFA", if(O32<26,4000,O32*150),if(F32="CSCDA",if(33<O32<300, O32*150,if(O32>300,(45000+(O32-300)*75),5000)))) -> 11850 | AL32: =if(AE32="YES",0,IF(AND(I32>=DATE(2022,7,1),I32<=DATE(2023,6,30)),3,IF(AND(I32>=DATE(2023,7,1),I32<=DATE(2024,6,30)),2,IF(AND(I32>=DATE(2024,7,1),I32<=DATE(2025,6,30)),1,IF(AND(I32>=DATE(2025,7,1),I32<=DATE(2026,6,30)),0,"-"))))) -> 0 | AM32: =AK32*AL32 -> 0 | AN32: {=_xlfn.xlookup(C32,'SCC Certificate Review'!C:C,'SCC Certificate Review'!F:F)}
A33: 27 | B33: Santa Monica Portfolio A Apartments | C33: GC 1422-1428 6th, LP | D33: Santa Monica | E33: Los Angeles | F33: CMFA | G33: Grant up to $10,000 | H33: 24-280 | I33: 45513 | K33: Gortikov Capital | M33: Kingdom Development, Inc. | N33: FALSE | O33: =28+24 -> 52 | P33: 32 | Q33: =P33/O33 -> 0.61538462 | R33: 1422-1428 6th St., Santa Monica, CA | S33: 4800 | T33: =COUNTIF(Parcels!A:A, A33) > 0 -> TRUE | U33: =MAXIFS(Parcels!AC:AC, Parcels!A:A, A33) > 0 -> TRUE | V33: =SUMIF(Parcels!A:A, A33, Parcels!Z:Z) -> 17170000 | W33: =SUMIF(Parcels!$A:$A, $A33, Parcels!AC:AC) -> 4062807 | X33: =V33*P33/O33*0.9 -> 9509538.5 | Y33: =IF(W33=0, X33, W33) -> 4062807 | Z33: {=_xlfn.XLOOKUP( A33, Parcels!A:A, Parcels!AL:AL)} -> 0.01203757 | AA33: =W33*Z33 -> 48906.324 | AB33: =Y33*Z33 -> 48906.324 | AC33: https://www.1422on6th.com/ | AE33: NO | AF33: 1997 | AG33: 17170000 | AH33: 45547 | AJ33: =if(F33="CMFA", if(O33<16,10000,O33*600),if(F33="CSCDA",if(33<O33<300, O33*600,if(O33>300,(180000+(O33-300)*300),20000)))) -> 31200 | AK33: =if(F33="CMFA", if(O33<26,4000,O33*150),if(F33="CSCDA",if(33<O33<300, O33*150,if(O33>300,(45000+(O33-300)*75),5000)))) -> 7800 | AL33: =if(AE33="YES",0,IF(AND(I33>=DATE(2022,7,1),I33<=DATE(2023,6,30)),3,IF(AND(I33>=DATE(2023,7,1),I33<=DATE(2024,6,30)),2,IF(AND(I33>=DATE(2024,7,1),I33<=DATE(2025,6,30)),1,IF(AND(I33>=DATE(2025,7,1),I33<=DATE(2026,6,30)),0,"-"))))) -> 1 | AM33: =AK33*AL33 -> 7800 | AN33: {=_xlfn.xlookup(C33,'SCC Certificate Review'!C:C,'SCC Certificate Review'!F:F)} -> TRUE
A34: 28 | B34: Santa Monica Portfolio B Apartments | C34: GC 1422-1432 7th, LP | D34: Santa Monica | E34: Los Angeles | F34: CMFA | G34: Grant up to $10,000 | H34: 24-281 | I34: 45513 | K34: Gortikov Capital | M34: Kingdom Development, Inc. | N34: FALSE | O34: =28+2*22 -> 72 | P34: 49 | Q34: =P34/O34 -> 0.68055556 | R34: 1422-1432 7th, Santa Monica, CA | S34: 7350 | T34: =COUNTIF(Parcels!A:A, A34) > 0 -> TRUE | U34: =MAXIFS(Parcels!AC:AC, Parcels!A:A, A34) > 0 -> TRUE | V34: =SUMIF(Parcels!A:A, A34, Parcels!Z:Z) -> 23070000 | W34: =SUMIF(Parcels!$A:$A, $A34, Parcels!AC:AC) -> 10578326 | X34: =V34*P34/O34*0.9 -> 14130375 | Y34: =IF(W34=0, X34, W34) -> 10578326 | Z34: {=_xlfn.XLOOKUP( A34, Parcels!A:A, Parcels!AL:AL)} -> 0.01203757 | AA34: =W34*Z34 -> 127337.34 | AB34: =Y34*Z34 -> 127337.34 | AJ34: =if(F34="CMFA", if(O34<16,10000,O34*600),"-") -> 43200 | AK34: =if(F34="CMFA", if(O34<26,4000,O34*150),"-") -> 10800 | AL34: =IF(AND(I34>=DATE(2022,7,1),I34<=DATE(2023,6,30)),3,IF(AND(I34>=DATE(2023,7,1),I34<=DATE(2024,6,30)),2,IF(AND(I34>=DATE(2024,7,1),I34<=DATE(2025,6,30)),1,IF(AND(I34>=DATE(2025,7,1),I34<=DATE(2026,6,30)),0,"-")))) -> 1 | AM34: =AK34*AL34 -> 10800 | AN34: {=_xlfn.xlookup(C34,'SCC Certificate Review'!C:C,'SCC Certificate Review'!F:F)} -> TRUE
A35: 29 | B35: Santa Monica Portfolio C Apartments | C35: GC 1423-1425 6th, LP | D35: Santa Monica | E35: Los Angeles | F35: CMFA | G35: Grant up to $10,000 | H35: 24-282 | I35: 45513 | K35: Gortikov Capital | M35: Kingdom Development, Inc. | N35: FALSE | O35: 48 | P35: 29 | Q35: =P35/O35 -> 0.60416667 | R35: 1423-1425 6th, Santa Monica, CA | S35: 4350 | T35: =COUNTIF(Parcels!A:A, A35) > 0 -> TRUE | U35: =MAXIFS(Parcels!AC:AC, Parcels!A:A, A35) > 0 -> TRUE | V35: =SUMIF(Parcels!A:A, A35, Parcels!Z:Z) -> 20900000 | W35: =SUMIF(Parcels!$A:$A, $A35, Parcels!AC:AC) -> 10886810 | X35: =V35*P35/O35*0.9 -> 11364375 | Y35: =IF(W35=0, X35, W35) -> 10886810 | Z35: {=_xlfn.XLOOKUP( A35, Parcels!A:A, Parcels!AL:AL)} -> 0.01203757 | AA35: =W35*Z35 -> 131050.74 | AB35: =Y35*Z35 -> 131050.74 | AJ35: =if(F35="CMFA", if(O35<16,10000,O35*600),if(F35="CSCDA",if(33<O35<300, O35*600,if(O35>300,(180000+(O35-300)*300),20000)))) -> 28800 | AK35: =if(F35="CMFA", if(O35<26,4000,O35*150),if(F35="CSCDA",if(33<O35<300, O35*150,if(O35>300,(45000+(O35-300)*75),5000)))) -> 7200 | AL35: =if(AE35="YES",0,IF(AND(I35>=DATE(2022,7,1),I35<=DATE(2023,6,30)),3,IF(AND(I35>=DATE(2023,7,1),I35<=DATE(2024,6,30)),2,IF(AND(I35>=DATE(2024,7,1),I35<=DATE(2025,6,30)),1,IF(AND(I35>=DATE(2025,7,1),I35<=DATE(2026,6,30)),0,"-"))))) -> 1 | AM35: =AK35*AL35 -> 7200 | AN35: {=_xlfn.xlookup(C35,'SCC Certificate Review'!C:C,'SCC Certificate Review'!F:F)} -> TRUE
A36: 30 | B36: Santa Monica Portfolio D Apartments | C36: GC 1522 6th, LP | D36: Santa Monica | E36: Los Angeles | F36: CMFA | G36: Grant up to $10,000 | H36: 24-283 | I36: 45513 | K36: Gortikov Capital | M36: Kingdom Development, Inc. | N36: FALSE | O36: 26 | P36: 25 | Q36: =P36/O36 -> 0.96153846 | R36: 1522 6th St, Santa Monica, CA | S36: 3750 | T36: =COUNTIF(Parcels!A:A, A36) > 0 -> TRUE | U36: =MAXIFS(Parcels!AC:AC, Parcels!A:A, A36) > 0 -> TRUE | V36: =SUMIF(Parcels!A:A, A36, Parcels!Z:Z) -> 7050000 | W36: =SUMIF(Parcels!$A:$A, $A36, Parcels!AC:AC) -> 3659058 | X36: =V36*P36/O36*0.9 -> 6100961.5 | Y36: =IF(W36=0, X36, W36) -> 3659058 | Z36: {=_xlfn.XLOOKUP( A36, Parcels!A:A, Parcels!AL:AL)} -> 0.01203757 | AA36: =W36*Z36 -> 44046.167 | AB36: =Y36*Z36 -> 44046.167 | AF36: 2004 | AJ36: =if(F36="CMFA", if(O36<16,10000,O36*600),if(F36="CSCDA",if(33<O36<300, O36*600,if(O36>300,(180000+(O36-300)*300),20000)))) -> 15600 | AK36: =if(F36="CMFA", if(O36<26,4000,O36*150),if(F36="CSCDA",if(33<O36<300, O36*150,if(O36>300,(45000+(O36-300)*75),5000)))) -> 3900 | AL36: =if(AE36="YES",0,IF(AND(I36>=DATE(2022,7,1),I36<=DATE(2023,6,30)),3,IF(AND(I36>=DATE(2023,7,1),I36<=DATE(2024,6,30)),2,IF(AND(I36>=DATE(2024,7,1),I36<=DATE(2025,6,30)),1,IF(AND(I36>=DATE(2025,7,1),I36<=DATE(2026,6,30)),0,"-"))))) -> 1 | AM36: =AK36*AL36 -> 3900 | AN36: {=_xlfn.xlookup(C36,'SCC Certificate Review'!C:C,'SCC Certificate Review'!F:F)} -> TRUE
A37: 31 | B37: Santa Monica Portfolio E Apartments | C37: GC 1537 7th, LP | D37: Santa Monica | E37: Los Angeles | F37: CMFA | G37: Grant up to $10,000 | H37: 24-284 | I37: 45513 | K37: Gortikov Capital | M37: Kingdom Development, Inc. | N37: FALSE | O37: 26 | P37: 25 | Q37: =P37/O37 -> 0.96153846 | R37: 1537 7th, Santa Monica, CA | S37: 3750 | T37: =COUNTIF(Parcels!A:A, A37) > 0 -> TRUE | U37: =MAXIFS(Parcels!AC:AC, Parcels!A:A, A37) > 0 -> TRUE | V37: =SUMIF(Parcels!A:A, A37, Parcels!Z:Z) -> 6580000 | W37: =SUMIF(Parcels!$A:$A, $A37, Parcels!AC:AC) -> 4088045 | X37: =V37*P37/O37*0.9 -> 5694230.8 | Y37: =IF(W37=0, X37, W37) -> 4088045 | Z37: {=_xlfn.XLOOKUP( A37, Parcels!A:A, Parcels!AL:AL)} -> 0.01203757 | AA37: =W37*Z37 -> 49210.128 | AB37: =Y37*Z37 -> 49210.128 | AG37: 5390000 | AH37: 45547 | AJ37: =if(F37="CMFA", if(O37<16,10000,O37*600),if(F37="CSCDA",if(33<O37<300, O37*600,if(O37>300,(180000+(O37-300)*300),20000)))) -> 15600 | AK37: =if(F37="CMFA", if(O37<26,4000,O37*150),if(F37="CSCDA",if(33<O37<300, O37*150,if(O37>300,(45000+(O37-300)*75),5000)))) -> 3900 | AL37: =if(AE37="YES",0,IF(AND(I37>=DATE(2022,7,1),I37<=DATE(2023,6,30)),3,IF(AND(I37>=DATE(2023,7,1),I37<=DATE(2024,6,30)),2,IF(AND(I37>=DATE(2024,7,1),I37<=DATE(2025,6,30)),1,IF(AND(I37>=DATE(2025,7,1),I37<=DATE(2026,6,30)),0,"-"))))) -> 1 | AM37: =AK37*AL37 -> 3900 | AN37: {=_xlfn.xlookup(C37,'SCC Certificate Review'!C:C,'SCC Certificate Review'!F:F)} -> TRUE
A38: 32 | B38: Santa Monica Portfolio F Apartments | C38: GC 2001-2029 Olympic, LP | D38: Santa Monica | E38: Los Angeles | F38: CMFA | G38: Grant up to $10,000 | H38: 24-285 | I38: 45513 | K38: Gortikov Capital | M38: Kingdom Development, Inc. | N38: FALSE | O38: 165 | P38: 98 | Q38: =P38/O38 -> 0.59393939 | R38: 2001-2029 Olympic Blvd, Santa Monica | S38: 14700 | T38: =COUNTIF(Parcels!A:A, A38) > 0 -> TRUE | U38: =MAXIFS(Parcels!AC:AC, Parcels!A:A, A38) > 0 -> TRUE | V38: =SUMIF(Parcels!A:A, A38, Parcels!Z:Z) -> 29350000 | W38: =SUMIF(Parcels!$A:$A, $A38, Parcels!AC:AC) -> 22352409 | X38: =V38*P38/O38*0.9 -> 15688909 | Y38: =IF(W38=0, X38, W38) -> 22352409 | Z38: {=_xlfn.XLOOKUP( A38, Parcels!A:A, Parcels!AL:AL)} -> 0.01203757 | AA38: =W38*Z38 -> 269068.69 | AB38: =Y38*Z38 -> 269068.69 | AF38: 2008 | AJ38: =if(F38="CMFA", if(O38<16,10000,O38*600),if(F38="CSCDA",if(33<O38<300, O38*600,if(O38>300,(180000+(O38-300)*300),20000)))) -> 99000 | AK38: =if(F38="CMFA", if(O38<26,4000,O38*150),if(F38="CSCDA",if(33<O38<300, O38*150,if(O38>300,(45000+(O38-300)*75),5000)))) -> 24750 | AL38: =if(AE38="YES",0,IF(AND(I38>=DATE(2022,7,1),I38<=DATE(2023,6,30)),3,IF(AND(I38>=DATE(2023,7,1),I38<=DATE(2024,6,30)),2,IF(AND(I38>=DATE(2024,7,1),I38<=DATE(2025,6,30)),1,IF(AND(I38>=DATE(2025,7,1),I38<=DATE(2026,6,30)),0,"-"))))) -> 1 | AM38: =AK38*AL38 -> 24750 | AN38: {=_xlfn.xlookup(C38,'SCC Certificate Review'!C:C,'SCC Certificate Review'!F:F)} -> TRUE
A39: 26 | B39: Harbor Terrace Apartments | C39: Post Harbor Terrace, LP | D39: Los Angeles | E39: Los Angeles | F39: CMFA | G39: Grant up to $10,000 | H39: 24-286 | I39: 45513 | K39: Ascenda Capital | M39: Integrity Housing | N39: FALSE | O39: 93 | P39: 93 | Q39: =P39/O39 -> 1 | R39: 441 W 3rd St, San Pedro, CA 90731 | S39: 13950 | T39: =COUNTIF(Parcels!A:A, A39) > 0 -> TRUE | U39: =MAXIFS(Parcels!AC:AC, Parcels!A:A, A39) > 0 -> TRUE | V39: =SUMIF(Parcels!A:A, A39, Parcels!Z:Z) -> 24250000 | W39: =SUMIF(Parcels!$A:$A, $A39, Parcels!AC:AC) -> 16429375 | X39: =V39*P39/O39*0.9 -> 21825000 | Y39: =IF(W39=0, X39, W39) -> 16429375 | Z39: {=_xlfn.XLOOKUP( A39, Parcels!A:A, Parcels!AL:AL)} -> 0.0118738 | AA39: =W39*Z39 -> 195079.11 | AB39: =Y39*Z39 -> 195079.11 | AF39: 1987 | AJ39: =if(F39="CMFA", if(O39<16,10000,O39*600),if(F39="CSCDA",if(33<O39<300, O39*600,if(O39>300,(180000+(O39-300)*300),20000)))) -> 55800 | AK39: =if(F39="CMFA", if(O39<26,4000,O39*150),if(F39="CSCDA",if(33<O39<300, O39*150,if(O39>300,(45000+(O39-300)*75),5000)))) -> 13950 | AL39: =if(AE39="YES",0,IF(AND(I39>=DATE(2022,7,1),I39<=DATE(2023,6,30)),3,IF(AND(I39>=DATE(2023,7,1),I39<=DATE(2024,6,30)),2,IF(AND(I39>=DATE(2024,7,1),I39<=DATE(2025,6,30)),1,IF(AND(I39>=DATE(2025,7,1),I39<=DATE(2026,6,30)),0,"-"))))) -> 1 | AM39: =AK39*AL39 -> 13950 | AN39: {=_xlfn.xlookup(C39,'SCC Certificate Review'!C:C,'SCC Certificate Review'!F:F)} -> TRUE
A40: 36 | B40: Stadium Village Apartments | C40: SV INGLEWOOD HOLDINGS, L.P., a California limited partnership | D40: Inglewood | E40: Los Angeles | F40: CMFA | G40: Grant up to $10,000 | H40: 24-361 | I40: 45534 | K40: Community HousingWorks | M40: Community HousingWorks | N40: FALSE | O40: 80 | P40: 80 | Q40: =P40/O40 -> 1 | R40: 9301 – 9609 Crenshaw Blvd, Inglewood, CA | S40: 12000 | T40: =COUNTIF(Parcels!A:A, A40) > 0 -> TRUE | U40: =MAXIFS(Parcels!AC:AC, Parcels!A:A, A40) > 0 -> FALSE | V40: =SUMIF(Parcels!A:A, A40, Parcels!Z:Z) -> 26900000 | W40: =SUMIF(Parcels!$A:$A, $A40, Parcels!AC:AC) -> 0 | X40: =V40*P40/O40*0.9 -> 24210000 | Y40: =IF(W40=0, X40, W40) -> 24210000 | Z40: {=_xlfn.XLOOKUP( A40, Parcels!A:A, Parcels!AL:AL)} -> 0.01280765 | AA40: =W40*Z40 -> 0 | AB40: =Y40*Z40 -> 310073.21 | AJ40: =if(F40="CMFA", if(O40<16,10000,O40*600),if(F40="CSCDA",if(33<O40<300, O40*600,if(O40>300,(180000+(O40-300)*300),20000)))) -> 48000 | AK40: =if(F40="CMFA", if(O40<26,4000,O40*150),if(F40="CSCDA",if(33<O40<300, O40*150,if(O40>300,(45000+(O40-300)*75),5000)))) -> 12000 | AL40: =if(AE40="YES",0,IF(AND(I40>=DATE(2022,7,1),I40<=DATE(2023,6,30)),3,IF(AND(I40>=DATE(2023,7,1),I40<=DATE(2024,6,30)),2,IF(AND(I40>=DATE(2024,7,1),I40<=DATE(2025,6,30)),1,IF(AND(I40>=DATE(2025,7,1),I40<=DATE(2026,6,30)),0,"-"))))) -> 1 | AM40: =AK40*AL40 -> 12000 | AN40: {=_xlfn.xlookup(C40,'SCC Certificate Review'!C:C,'SCC Certificate Review'!F:F)} -> TRUE
...

Sheet Parcels
A1: project_id | B1: county | C1: property | D1: ain | E1: legacy_ain | F1: legacy_redundant | G1: apn | H1: situs_address | I1: situs_city | J1: situs_zip | K1: input_address | L1: property_name | M1: tract_number | N1: method | O1: use_description | P1: use_type | Q1: use_code | R1: year_built | S1: units | T1: bedrooms | U1: bathrooms | V1: sqft | W1: roll_year | X1: roll_land_value | Y1: roll_imp_value | Z1: roll_total_value | AA1: roll_land_base_year | AB1: roll_imp_base_year | AC1: real_estate_exemp | AD1: tax_rate_area | AE1: tax_rate_city | AF1: latitude | AG1: longitude | AH1: legal_description | AI1: notes | AJ1: CMFA Total Units | AK1: CMFA Restricted | AL1: Total Tax Rate
A2: 1 | B2: {=_xlfn.XLOOKUP( A2, 'CMFA-CSCDA Grants'!A:A, 'CMFA-CSCDA Grants'!E:E)} -> Los Angeles | C2: {=_xlfn.XLOOKUP( A2, 'CMFA-CSCDA Grants'!A:A, 'CMFA-CSCDA Grants'!B:B)} -> Alvarado Streets Apartments | D2: 5136019013 | F2: FALSE | G2: 5136-019-013 | H2: 1136 S ALVARADO ST LOS ANGELES CA 90006 | I2: LOS ANGELES CA | J2: 90006-4138 | K2: 1136 S. Alvarado Street, Los Angeles, CA | L2: Alvarado Streets Apartments | N2: manual_verified | O2: Five or more apartments | P2: Residential | Q2: 500 | R2: 1912 | S2: 24 | T2: 0 | U2: 24 | V2: 16113 | W2: 2025 | X2: 2080800 | Y2: 2366910 | Z2: =SUM(X2:Y2) -> 4447710 | AA2: 2023 | AB2: 2023 | AC2: 4262686 | AD2: 36 | AE2: LOS ANGELES | AF2: 34.04914 | AG2: -118.28104 | AH2: ALVARADO HEIGHTS LOT 4 BLK 6 | AI2: Corrected from AIN 5136019023 (auto/equipment use) to 5136019013 (apartments) | AJ2: {=_xlfn.XLOOKUP( A2, 'CMFA-CSCDA Grants'!A:A, 'CMFA-CSCDA Grants'!O:O)} -> 24 | AK2: {=_xlfn.XLOOKUP( A2, 'CMFA-CSCDA Grants'!A:A, 'CMFA-CSCDA Grants'!P:P)} -> 24 | AL2: {=_xlfn.XLOOKUP( AD2, 'Tax Rates'!A:A, 'Tax Rates'!B:B)} -> 0.0118738
A3: 2 | B3: {=_xlfn.XLOOKUP( A3, 'CMFA-CSCDA Grants'!A:A, 'CMFA-CSCDA Grants'!E:E)} -> Los Angeles | C3: {=_xlfn.XLOOKUP( A3, 'CMFA-CSCDA Grants'!A:A, 'CMFA-CSCDA Grants'!B:B)} -> 2025 New Jersey Apartments | D3: 5183001017 | F3: FALSE | G3: 5183-001-017 | H3: 2025 NEW JERSEY ST LOS ANGELES CA 90033 | I3: LOS ANGELES CA | J3: 90033-2805 | K3: 2025 New Jersey St, Los Angeles, CA | L3: 2025 New Jersey Apartments | N3: manual_verified | O3: Five or more apartments | P3: Residential | Q3: 050V | W3: 2025 | X3: 527950 | Y3: 0 | Z3: =SUM(X3:Y3) -> 527950 | AA3: 2018 | AB3: 2018 | AC3: 527950 | AD3: 4 | AE3: LOS ANGELES | AF3: 34.048011 | AG3: -118.21232 | AH3: SUBDN OF LOT 2 BLK 60 H S NW 20 FT OF LOT 3 AND SE 20 FT OF LOT 5 BLK A | AJ3: {=_xlfn.XLOOKUP( A3, 'CMFA-CSCDA Grants'!A:A, 'CMFA-CSCDA Grants'!O:O)} -> 15 | AK3: {=_xlfn.XLOOKUP( A3, 'CMFA-CSCDA Grants'!A:A, 'CMFA-CSCDA Grants'!P:P)} -> 14 | AL3: {=_xlfn.XLOOKUP( AD3, 'Tax Rates'!A:A, 'Tax Rates'!B:B)} -> 0.0118738
A4: 3 | B4: {=_xlfn.XLOOKUP( A4, 'CMFA-CSCDA Grants'!A:A, 'CMFA-CSCDA Grants'!E:E)} -> Santa Clara | C4: {=_xlfn.XLOOKUP( A4, 'CMFA-CSCDA Grants'!A:A, 'CMFA-CSCDA Grants'!B:B)} -> Mariposa Club Apartments | D4: 15434025 | F4: FALSE | H4: 660 MARIPOSA AVE MOUNTAIN VIEW CA 94041-1867 | X4: - | Y4: - | Z4: 17059601 | AC4: 16718409 | AD4: Mountain View | AJ4: {=_xlfn.XLOOKUP( A4, 'CMFA-CSCDA Grants'!A:A, 'CMFA-CSCDA Grants'!O:O)} -> 48 | AK4: {=_xlfn.XLOOKUP( A4, 'CMFA-CSCDA Grants'!A:A, 'CMFA-CSCDA Grants'!P:P)} -> 48 | AL4: {=_xlfn.XLOOKUP( AD4, 'Tax Rates'!A:A, 'Tax Rates'!B:B)} -> 0.011211
A5: 4 | B5: {=_xlfn.XLOOKUP( A5, 'CMFA-CSCDA Grants'!A:A, 'CMFA-CSCDA Grants'!E:E)} -> San Bernardino | C5: {=_xlfn.XLOOKUP( A5, 'CMFA-CSCDA Grants'!A:A, 'CMFA-CSCDA Grants'!B:B)} -> Bernardine Apartments | D5: 147091180000 | F5: FALSE | H5: 363 E GILBERT ST SAN BERNARDINO CA 92404-5343 | X5: - | Y5: - | Z5: 4156500 | AC5: 4156500 | AD5: San Bernardino | AJ5: {=_xlfn.XLOOKUP( A5, 'CMFA-CSCDA Grants'!A:A, 'CMFA-CSCDA Grants'!O:O)} -> 71 | AK5: {=_xlfn.XLOOKUP( A5, 'CMFA-CSCDA Grants'!A:A, 'CMFA-CSCDA Grants'!P:P)} -> 70 | AL5: {=_xlfn.XLOOKUP( AD5, 'Tax Rates'!A:A, 'Tax Rates'!B:B)} -> 0.0113
A6: 5 | B6: {=_xlfn.XLOOKUP( A6, 'CMFA-CSCDA Grants'!A:A, 'CMFA-CSCDA Grants'!E:E)} -> San Diego | C6: {=_xlfn.XLOOKUP( A6, 'CMFA-CSCDA Grants'!A:A, 'CMFA-CSCDA Grants'!B:B)} -> City View aka Outlook at Mission Valley Apartments | D6: 5343602100 | F6: FALSE | H6: 840.0 17TH ST SAN DIEGO CA 92101-6666 | X6: - | Y6: - | Z6: 9316117 | AD6: San Diego | AJ6: {=_xlfn.XLOOKUP( A6, 'CMFA-CSCDA Grants'!A:A, 'CMFA-CSCDA Grants'!O:O)} -> 56 | AK6: {=_xlfn.XLOOKUP( A6, 'CMFA-CSCDA Grants'!A:A, 'CMFA-CSCDA Grants'!P:P)} -> 23 | AL6: {=_xlfn.XLOOKUP( AD6, 'Tax Rates'!A:A, 'Tax Rates'!B:B)} -> 0.0125114
